<?xml version="1.0" encoding="utf-8"?>
<!-- This URDF was automatically created by SolidWorks to URDF Exporter! Originally created by Stephen Brawner (brawner@gmail.com) 
     Commit Version: 1.6.0-1-g15f4949  Build Version: 1.6.7594.29634
     For more information, please see http://wiki.ros.org/sw_urdf_exporter -->
<robot name="urdf_trex">

  <!-- ##################################################################### -->
<!--   <link name="root">
    <visual>
      <origin rpy="0 0 0" xyz="0 0 0"/>
      <geometry>
        <box size="0.001 0.001 0.001"/>
      </geometry>
    </visual>
    <collision>
      <origin rpy="0 0 0" xyz="0 0 0"/>
      <geometry>
        <box size="0.001 0.001 0.001"/>
      </geometry>
    </collision>
  </link> -->

  <!-- for gazebo -->
<!--   <link name="world"/>
  <joint name="connect_root_and_world" type="fixed">
    <parent link="world"/>
    <child link="root"/>
    <origin rpy="0 0 0" xyz="0 0 0"/>
  </joint> -->


  <link name="world"/>


<!-- ####################################################################### -->
  
  <link name="link_1">
    <inertial>
      <origin
        xyz="0.0076727 0.0054019 -0.029767"
        rpy="0 0 0" />
      <mass
        value="1.3375" />
      <inertia
        ixx="0.0025718"
        ixy="-2.7062E-07"
        ixz="3.1714E-06"
        iyy="0.00083515"
        iyz="1.5387E-06"
        izz="0.0030326" />
    </inertial>
    <visual>
      <origin
        xyz="0 0 0"
        rpy="0 0 0" />
      <geometry>
        <mesh
          filename="package://urdf_trex/meshes/link_1.STL" />
      </geometry>
      <material
        name="">
        <color
          rgba="0.75294 0.75294 0.75294 1" />
      </material>
    </visual>
    <collision>
      <origin
        xyz="0 0 0"
        rpy="0 0 0" />
      <geometry>
        <mesh
          filename="package://urdf_trex/meshes/link_1.STL" />
      </geometry>
    </collision>
  </link>

<!-- +++++++++++++++++++++++++++++++++++++++++++++++++++++++++++++++++ -->

  <joint name="virtual_joint" type="fixed">
    <parent link="world"/>
    <child link="link_1"/>
    <origin rpy="0 0 0" xyz="0.1 0.1 0.1"/>
    <dynamics damping="100" friction="100.0" />
  </joint>

 <!--   <joint
    name="joint_base"
    type="fixed">
    <origin
      xyz="0 0 0"
      rpy="0 0 0" />
    <parent
      link="root" />
    <child
      link="link_1" />
    <axis xyz="0 0 1" />
    <limit effort="2000" velocity="0.1"/>
  </joint> -->
  <!-- ++++++++++++++++++++++++++++++++++++++++++++++++++++++++++++++++++ -->

  <link name="link_2">
    <inertial>
      <origin
        xyz="-0.011229 0.00033042 0.052202"
        rpy="0 0 0" />
      <mass
        value="2.9992" />
      <inertia
        ixx="0.0015389"
        ixy="2.3934E-05"
        ixz="2.49E-05"
        iyy="0.0018893"
        iyz="2.8767E-07"
        izz="0.0013144" />
    </inertial>
    <visual>
      <origin
        xyz="0 0 0"
        rpy="0 0 0" />
      <geometry>
        <mesh
          filename="package://urdf_trex/meshes/link_2.STL" />
      </geometry>
      <material
        name="">
        <color
          rgba="0.75294 0.75294 0.75294 1" />
      </material>
    </visual>
    <collision>
      <origin
        xyz="0 0 0"
        rpy="0 0 0" />
      <geometry>
        <mesh
          filename="package://urdf_trex/meshes/link_2.STL" />
      </geometry>
    </collision>
  </link>

  <joint
    name="joint_1" type="revolute" >
    <origin
      xyz="0 0 0"
      rpy="0 0 0" />
    <parent
      link="link_1" />
    <child
      link="link_2" />
    <axis xyz="0 0 1" />
    <limit effort="100" velocity="30" upper="3.14" lower="-3.14"/>
    <dynamics damping="0.7"/>
<!--<limit effort="30" velocity="1.0" lower="-3.14" upper="3.14"  />--> 
<!-- soft_lower_limit="-3.14" soft_upper_limit="3.14"-->  
 </joint>

  <link
    name="link_3">
    <inertial>
      <origin
        xyz="0.13008 -0.023939 0.20948"
        rpy="0 0 0" />
      <mass
        value="2.1045" />
      <inertia
        ixx="0.0052536"
        ixy="7.2696E-05"
        ixz="-0.0028911"
        iyy="0.0076699"
        iyz="0.000102"
        izz="0.0028991" />
    </inertial>
    <visual>
      <origin
        xyz="0 0 0"
        rpy="0 0 0" />
      <geometry>
        <mesh
          filename="package://urdf_trex/meshes/link_3.STL" />
      </geometry>
      <material
        name="">
        <color
          rgba="0.75294 0.75294 0.75294 1" />
      </material>
    </visual>
    <collision>
      <origin
        xyz="0 0 0"
        rpy="0 0 0" />
      <geometry>
        <mesh
          filename="package://urdf_trex/meshes/link_3.STL" />
      </geometry>
    </collision>
  </link>

  <joint
    name="joint_2" type="revolute" >

    <origin
      xyz="0 0 0.0589"
      rpy="0 0 0" />
    <parent
      link="link_2" />
    <child
      link="link_3" />
    <axis
      xyz="0.02371 0.99972 0" />
    <limit effort="100" velocity="30" upper="3.14" lower="-3.14"/>
    <dynamics damping="0.7"/>
    <!-- <limit effort="100" velocity="10" /> -->
  </joint>

  <link
    name="link_4">
    <inertial>
      <origin
        xyz="0.14285 0.0030142 -0.10585"
        rpy="0 0 0" />
      <mass value="0.962" /> 
      <inertia
        ixx="0.00064228"
        ixy="2.3991E-05"
        ixz="0.00065305"
        iyy="0.0017112"
        iyz="-1.3429E-05"
        izz="0.0011651" />
    </inertial>
    <visual>
      <origin
        xyz="0 0 0"
        rpy="0 0 0" />
      <geometry>
        <mesh
          filename="package://urdf_trex/meshes/link_4.STL" />
      </geometry>
      <material
        name="">
        <color
          rgba="0.75294 0.75294 0.75294 1" />
      </material>
    </visual>
    <collision>
      <origin
        xyz="0 0 0"
        rpy="0 0 0" />
      <geometry>
        <mesh
          filename="package://urdf_trex/meshes/link_4.STL" />
      </geometry>
    </collision>
  </link>

  <joint
    name="joint_3" type="revolute" >

    <origin
      xyz="0.16899 -0.0040079 0.24784"
      rpy="0 0 0" />
    <parent
      link="link_3" />
    <child
      link="link_4" />
    <axis
      xyz="0.02371 0.99972 0" />
    <limit effort="100" velocity="30" upper="3.14" lower="-3.14"/>
    <dynamics damping="0.7"/>
    <!-- <limit effort="100" velocity="10" /> -->
  </joint>

  <link
    name="link_5">
    <inertial>
      <origin
        xyz="0.078859 0.0015191 0.018505"
        rpy="0 0 0" />
      <mass value="0.7665" /> 
      <inertia
        ixx="0.00017692"
        ixy="-1.3281E-05"
        ixz="-5.3311E-06"
        iyy="0.00025322"
        iyz="-2.3353E-06"
        izz="0.00026405" />
    </inertial>
    <visual>
      <origin
        xyz="0 0 0"
        rpy="0 0 0" />
      <geometry>
        <mesh
          filename="package://urdf_trex/meshes/link_5.STL" />
      </geometry>
      <material
        name="">
        <color
          rgba="0.75294 0.75294 0.75294 1" />
      </material>
    </visual>
    <collision>
      <origin
        xyz="0 0 0"
        rpy="0 0 0" />
      <geometry>
        <mesh
          filename="package://urdf_trex/meshes/link_5.STL" />
      </geometry>
    </collision>
  </link>

  <joint
    name="joint_4" type="revolute" >
    <origin
      xyz="0.18659 -0.0044253 -0.12566"
      rpy="0 0 0" />
    <parent
      link="link_4" />
    <child
      link="link_5" />
    <axis
      xyz="0.02371 0.99972 0" />
    <limit effort="100" velocity="30" upper="3.14" lower="-3.14"/>
    <dynamics damping="0.7"/>
   <!--  <limit effort="100" velocity="10" />  -->
  </joint>

  <!--     <limit effort="87" lower="-3.14" upper="3.14" velocity="2.1750" />-->
 

  <!-- ros_control plugin -->
  <gazebo>
    <!--To link Gazebo and ROS, we specify the plugin in the URDF-->
    <plugin name="gazebo_ros_control" filename="libgazebo_ros_control.so">
      <robotNamespace>/urdf_trex</robotNamespace>
      <robotSimType>gazebo_ros_control/DefaultRobotHWSim</robotSimType>
      <legacyModeNS>true</legacyModeNS>
    </plugin>
  </gazebo>


  <!-- Link1 -->
  <gazebo reference="link_1">
    <static>true</static>
    <material>Gazebo/Blue</material>
  </gazebo>

  <!-- Link2 -->
  <gazebo reference="link_2">
    <mu1>1.0</mu1>
    <mu2>1.0</mu2>
    <dynamics damping="7" friction="100.0" />
    <!-- <fdir1>0 0 1</fdir1> --> <!-- Is that correct? -->
    <material>Gazebo/Red</material>
  </gazebo>

  <!-- Link3 -->
  <gazebo reference="link_3">
    <mu1>1.0</mu1>
    <mu2>1.0</mu2>
    <dynamics damping="7" friction="100.0" />
    <fdir1>0 1 0</fdir1>
    <material>Gazebo/Orange</material>
  </gazebo>

    <!-- Link4 -->
  <gazebo reference="link_4">
    <mu1>1.0</mu1>
    <mu2>1.0</mu2>
    <dynamics damping="7" friction="100.0" />
    <fdir1>0 1 0</fdir1>   
    <material>Gazebo/White</material>
  </gazebo>

    <!-- Link5 -->
  <gazebo reference="link_5">
    <mu1>1.0</mu1>
    <mu2>1.0</mu2>
    <dynamics damping="7" friction="100.0" />
    <fdir1>0 1 0</fdir1> 
    <material>Gazebo/Green</material>
  </gazebo>

<!--   <gazebo reference="virtual_joint">
      <disableFixedJointLumping>true</disableFixedJointLumping>
  </gazebo> -->



  <!-- This block connects the joints to actuators (motor), which inform both
  simulation and visualization of the robot -->

  <transmission name="joint_1_trans">
    <type>transmission_interface/SimpleTransmission</type>
    <joint name="joint_1">
      <!-- <hardwareInterface>hardware_interface/PositionJointInterface</hardwareInterface> -->
      <hardwareInterface>hardware_interface/EffortJointInterface</hardwareInterface>
    </joint>
    <actuator name="$joint_1_motor">      
      <!-- <hardwareInterface>hardware_interface/PositionJointInterface</hardwareInterface> -->
      <hardwareInterface>hardware_interface/EffortJointInterface</hardwareInterface>
      <mechanicalReduction>1</mechanicalReduction>
    </actuator>
  </transmission>

<!--   <hardwareInterface>hardware_interface/PositionJointInterface</hardwareInterface>
hardware_interface/EffortJointInterface
 -->

  <transmission name="joint_2_trans">
    <type>transmission_interface/SimpleTransmission</type>
    <joint name="joint_2">
      <!-- <hardwareInterface>hardware_interface/PositionJointInterface</hardwareInterface> -->
      <hardwareInterface>hardware_interface/EffortJointInterface</hardwareInterface>
    </joint>
    <actuator name="$joint_2_motor">
      <!-- <hardwareInterface>hardware_interface/PositionJointInterface</hardwareInterface> -->
      <hardwareInterface>hardware_interface/EffortJointInterface</hardwareInterface>
      <mechanicalReduction>1</mechanicalReduction>
    </actuator>
  </transmission>

  <transmission name="joint_3_trans">
    <type>transmission_interface/SimpleTransmission</type>
    <joint name="joint_3">
      <!-- <hardwareInterface>hardware_interface/PositionJointInterface</hardwareInterface> -->
      <hardwareInterface>hardware_interface/EffortJointInterface</hardwareInterface>
    </joint>
    <actuator name="$joint_3_motor">
      <!-- <hardwareInterface>hardware_interface/PositionJointInterface</hardwareInterface> -->
      <hardwareInterface>hardware_interface/EffortJointInterface</hardwareInterface>
      <mechanicalReduction>1</mechanicalReduction>
    </actuator>
  </transmission>

  <transmission name="joint_4_trans">
    <type>transmission_interface/SimpleTransmission</type>
    <joint name="joint_4">
      <!-- <hardwareInterface>hardware_interface/PositionJointInterface</hardwareInterface> -->
      <hardwareInterface>hardware_interface/EffortJointInterface</hardwareInterface>
    </joint>
    <actuator name="$joint_4_motor">
      <!-- <hardwareInterface>hardware_interface/PositionJointInterface</hardwareInterface> -->
      <hardwareInterface>hardware_interface/EffortJointInterface</hardwareInterface>
      <mechanicalReduction>1</mechanicalReduction>
    </actuator>
  </transmission>

</robot>