<?xml version="1.0" ?>
<!-- =================================================================================== -->
<!-- |    This document was autogenerated by xacro from urdf_trex.urdf                 | -->
<!-- |    EDITING THIS FILE BY HAND IS NOT RECOMMENDED                                 | -->
<!-- =================================================================================== -->
<!-- This URDF was automatically created by SolidWorks to URDF Exporter! Originally created by Stephen Brawner (brawner@gmail.com) 
     Commit Version: 1.6.0-1-g15f4949  Build Version: 1.6.7594.29634
     For more information, please see http://wiki.ros.org/sw_urdf_exporter -->
<robot name="urdf_trex">
 
  <link name="link_1">
    <inertial>
      <origin rpy="0 0 0" xyz="0.0076727 0.0054019 -0.029767"/>
      <mass value="1.3375"/>
      <inertia ixx="0.0025718" ixy="-2.7062E-07" ixz="3.1714E-06" iyy="0.00083515" iyz="1.5387E-06" izz="0.0030326"/>
    </inertial>
    <visual>
      <origin rpy="0 0 0" xyz="0 0 0"/>
      <geometry>
        <mesh filename="package://urdf_trex/meshes/link_1.STL"/>
      </geometry>
      <material name="">
        <color rgba="0.75294 0.75294 0.75294 1"/>
      </material>
    </visual>
    <collision>
      <origin rpy="0 0 0" xyz="0 0 0"/>
      <geometry>
        <mesh filename="package://urdf_trex/meshes/link_1.STL"/>
      </geometry>
    </collision>
  </link>

  <link name="link_2">
    <inertial>
      <origin rpy="0 0 0" xyz="-0.011229 0.00033042 0.052202"/>
      <mass value="2.9992"/>
      <inertia ixx="0.0015389" ixy="2.3934E-05" ixz="2.49E-05" iyy="0.0018893" iyz="2.8767E-07" izz="0.0013144"/>
    </inertial>
    <visual>
      <origin rpy="0 0 0" xyz="0 0 0"/>
      <geometry>
        <mesh filename="package://urdf_trex/meshes/link_2.STL"/>
      </geometry>
      <material name="">
        <color rgba="0.75294 0.75294 0.75294 1"/>
      </material>
    </visual>
    <collision>
      <origin rpy="0 0 0" xyz="0 0 0"/>
      <geometry>
        <mesh filename="package://urdf_trex/meshes/link_2.STL"/>
      </geometry>
    </collision>
  </link>

  <joint name="joint_1" type="continuous">
    <origin rpy="0 0 0" xyz="0 0 0"/>
    <parent link="link_1"/>
    <child link="link_2"/>
    <axis xyz="0 0 1"/>
    <limit effort="30" velocity="1.0"/>
  </joint>

  <link name="link_3">
    <inertial>
      <origin rpy="0 0 0" xyz="0.13008 -0.023939 0.20948"/>
      <mass value="2.1045"/>
      <inertia ixx="0.0052536" ixy="7.2696E-05" ixz="-0.0028911" iyy="0.0076699" iyz="0.000102" izz="0.0028991"/>
    </inertial>
    <visual>
      <origin rpy="0 0 0" xyz="0 0 0"/>
      <geometry>
        <mesh filename="package://urdf_trex/meshes/link_3.STL"/>
      </geometry>
      <material name="">
        <color rgba="0.75294 0.75294 0.75294 1"/>
      </material>
    </visual>
    <collision>
      <origin rpy="0 0 0" xyz="0 0 0"/>
      <geometry>
        <mesh filename="package://urdf_trex/meshes/link_3.STL"/>
      </geometry>
    </collision>
  </link>

  <joint name="joint_2" type="continuous">
    <origin rpy="0 0 0" xyz="0 0 0.0589"/>
    <parent link="link_2"/>
    <child link="link_3"/>
    <axis xyz="0.02371 0.99972 0"/>
    <limit effort="30" velocity="1.0"/>
  </joint>

  <link name="link_4">
    <inertial>
      <origin rpy="0 0 0" xyz="0.14285 0.0030142 -0.10585"/>
      <mass value="0.962"/>
      <inertia ixx="0.00064228" ixy="2.3991E-05" ixz="0.00065305" iyy="0.0017112" iyz="-1.3429E-05" izz="0.0011651"/>
    </inertial>
    <visual>
      <origin rpy="0 0 0" xyz="0 0 0"/>
      <geometry>
        <mesh filename="package://urdf_trex/meshes/link_4.STL"/>
      </geometry>
      <material name="">
        <color rgba="0.75294 0.75294 0.75294 1"/>
      </material>
    </visual>
    <collision>
      <origin rpy="0 0 0" xyz="0 0 0"/>
      <geometry>
        <mesh filename="package://urdf_trex/meshes/link_4.STL"/>
      </geometry>
    </collision>
  </link>

  <joint name="joint_3" type="continuous">
    <origin rpy="0 0 0" xyz="0.16899 -0.0040079 0.24784"/>
    <parent link="link_3"/>
    <child link="link_4"/>
    <axis xyz="0.02371 0.99972 0"/>
    <limit effort="30" velocity="1.0"/>
  </joint>

  <link name="link_5">
    <inertial>
      <origin rpy="0 0 0" xyz="0.078859 0.0015191 0.018505"/>
      <mass value="0.7665"/>
      <inertia ixx="0.00017692" ixy="-1.3281E-05" ixz="-5.3311E-06" iyy="0.00025322" iyz="-2.3353E-06" izz="0.00026405"/>
    </inertial>
    <visual>
      <origin rpy="0 0 0" xyz="0 0 0"/>
      <geometry>
        <mesh filename="package://urdf_trex/meshes/link_5.STL"/>
      </geometry>
      <material name="">
        <color rgba="0.75294 0.75294 0.75294 1"/>
      </material>
    </visual>
    <collision>
      <origin rpy="0 0 0" xyz="0 0 0"/>
      <geometry>
        <mesh filename="package://urdf_trex/meshes/link_5.STL"/>
      </geometry>
    </collision>
  </link>

  <joint name="joint_4" type="continuous">
    <origin rpy="0 0 0" xyz="0.18659 -0.0044253 -0.12566"/>
    <parent link="link_4"/>
    <child link="link_5"/>
    <axis xyz="0.02371 0.99972 0"/>
    <limit effort="30" velocity="1.0"/>
  </joint>

  <!-- This block connects the head_swivel joint to an actuator (motor), which informs both
    simulation and visualization of the robot -->

  <transmission name="joint_1_trans">
    <type>transmission_interface/SimpleTransmission</type>
    <actuator name="$joint_1_motor">
      <mechanicalReduction>1</mechanicalReduction>
    </actuator>
    <joint name="joint_1">
      <hardwareInterface>hardware_interface/PositionJointInterface</hardwareInterface>
    </joint>
  </transmission>

  <transmission name="joint_2_trans">
    <type>transmission_interface/SimpleTransmission</type>
    <actuator name="$joint_2_motor">
      <mechanicalReduction>1</mechanicalReduction>
    </actuator>
    <joint name="joint_2">
      <hardwareInterface>hardware_interface/PositionJointInterface</hardwareInterface>
    </joint>
  </transmission>

  <transmission name="joint_3_trans">
    <type>transmission_interface/SimpleTransmission</type>
    <actuator name="$joint_3_motor">
      <mechanicalReduction>1</mechanicalReduction>
    </actuator>
    <joint name="joint_3">
      <hardwareInterface>hardware_interface/PositionJointInterface</hardwareInterface>
    </joint>
  </transmission>

  <transmission name="joint_4_trans">
    <type>transmission_interface/SimpleTransmission</type>
    <actuator name="$joint_4_motor">
      <mechanicalReduction>1</mechanicalReduction>
    </actuator>
    <joint name="joint_4">
      <hardwareInterface>hardware_interface/PositionJointInterface</hardwareInterface>
    </joint>
  </transmission>

  <gazebo>
    <!--To link Gazebo and ROS, we specify the plugin in the URDF-->
    <plugin filename="libgazebo_ros_control.so" name="gazebo_ros_control">
      <robotSimType>gazebo_ros_control/DefaultRobotHWSim</robotSimType>
      <legacyModeNS>true</legacyModeNS>
      <robotNamespace>trex</robotNamespace>
    </plugin>
  </gazebo>



  <!--<gazebo reference="link_1">
    <sensor type="ray" name="head_hokuyo_sensor">
      <pose>0 0 0 0 0 0</pose>
      <visualize>true</visualize>
      <update_rate>40</update_rate>
      <ray>
        <scan>
          <horizontal>
            <samples>720</samples>
            <resolution>1</resolution>
            <min_angle>-1.570796</min_angle>
            <max_angle>1.570796</max_angle>
          </horizontal>
        </scan>
        <range>
          <min>0.10</min>
          <max>30.0</max>
          <resolution>0.01</resolution>
        </range>
        <noise>
          <type>gaussian</type>
           Noise parameters based on published spec for Hokuyo laser
               achieving "+-30mm" accuracy at range < 10m.  A mean of 0.0m and
               stddev of 0.01m will put 99.7% of samples within 0.03m of the true
               reading. 
          <mean>0.0</mean>
          <stddev>0.01</stddev>
        </noise>
      </ray>
      <plugin name="gazebo_ros_head_hokuyo_controller" filename="libgazebo_ros_laser.so">
        <topicName>/rrbot/laser/scan</topicName>
        <frameName>hokuyo_link</frameName>
      </plugin>
    </sensor>
  </gazebo>
  -->



  <!--World Link
  <link name="world"/>
  <joint name="world_joint" type="fixed" >
    <parent link="world" />
    <origin xyz="0 0 0" rpy="0 0 0" />
    <child link="link_1" />
	</joint> -->

</robot>
