<?xml version="1.0" ?>
<!-- =================================================================================== -->
<!-- |    This document was autogenerated by xacro from mrcp_trex_gripper.urdf         | -->
<!-- |    EDITING THIS FILE BY HAND IS NOT RECOMMENDED                                 | -->
<!-- =================================================================================== -->
<!-- =================================================================================== -->
<!-- |    This document was autogenerated by xacro from model.xacro                    | -->
<!-- |    EDITING THIS FILE BY HAND IS NOT RECOMMENDED                                 | -->
<!-- =================================================================================== -->
<robot name="mrcp_trex_gripper">
  <link name="body_footprint"/>

  <joint name="fixed" type="fixed">
    <origin rpy="0 0 0" xyz="0 0 0.3"/>
    <parent link="body_footprint"/>
    <child link="body"/>
  </joint> 

  <!--++++++++++++++++++++++++++++++++++++++++++++     MRCP links and joints   ++++++++++++++++++++++++++++++++++++++++++++++++++++++++++-->

  <link name="body">
    <inertial>
      <mass value="5"/>
      <origin rpy="0  0  0" xyz="0 0 0.125"/>
      <inertia ixx="0.02050030" ixy="0" ixz="0" iyy="0.05700340" iyz="0" izz="0.05769180"/>
    </inertial>
    <collision>
      <origin rpy="0  0  0" xyz="0 0 0"/>
      <geometry>
        <mesh filename="package://mrcp_trex_gripper_description/meshes/base.STL" scale="1 1 1"/>
      </geometry>
    </collision>
    <visual>
      <origin rpy="0  0  0" xyz="0 0 0"/>
      <geometry>
        <mesh filename="package://mrcp_trex_gripper_description/meshes/base.STL" scale="1 1 1"/>
      </geometry>
    </visual>
  </link>
  <link name="Right_Rocker">
    <inertial>
      <mass value="0.5"/>
      <origin rpy="0  0  0" xyz="-0.10 0.11 0"/>
      <inertia ixx="0.00335" ixy="0" ixz="0" iyy="0.0224" iyz="0" izz="0.02345"/>
    </inertial>
    <collision>
      <origin rpy="0  0  0" xyz="0 0 0"/>
      <geometry>
        <mesh filename="package://mrcp_trex_gripper_description/meshes/LLArm.STL" scale="1 1 1"/>
      </geometry>
    </collision>
    <visual>
      <origin rpy="0  0  0" xyz="0 0 0"/>
      <geometry>
        <mesh filename="package://mrcp_trex_gripper_description/meshes/LLArm.STL" scale="1 1 1"/>
      </geometry>
    </visual>
  </link>
  <joint name="Right_Rocker_joint" type="fixed">
    <parent link="body"/>
    <child link="Right_Rocker"/>
    <origin rpy="0 0 0" xyz="0 0.136 0.03"/>
    <axis xyz="0 1 0"/>
    <limit effort="10" lower="-0.7853" upper="0.7853" velocity="20"/>
    <dynamics damping="1" friction="1"/>
  </joint>
  <link name="Left_Rocker">
    <inertial>
      <mass value="0.5"/>
      <origin rpy="0  0  0" xyz="-0.10 -0.11 0"/>
      <inertia ixx="0.00335" ixy="0" ixz="0" iyy="0.0224" iyz="0" izz="0.02345"/>
    </inertial>
    <collision>
      <origin rpy="0  0  0" xyz="0 0 0"/>
      <geometry>
        <mesh filename="package://mrcp_trex_gripper_description/meshes/RLArm.STL" scale="1 1 1"/>
      </geometry>
    </collision>
    <visual>
      <origin rpy="0  0  0" xyz="0 0 0"/>
      <geometry>
        <mesh filename="package://mrcp_trex_gripper_description/meshes/RLArm.STL" scale="1 1 1"/>
      </geometry>
    </visual>
  </link>
  <joint name="Left_Rocker_joint" type="fixed">
    <parent link="body"/>
    <child link="Left_Rocker"/>
    <origin rpy="0 0 0" xyz="0 -0.136 0.03"/>
    <axis xyz="0 1 0"/>
    <limit effort="10" lower="-0.7853" upper="0.7853" velocity="20"/>
    <dynamics damping="1" friction="1"/>
  </joint>
  <link name="Right_Bogie">
    <inertial>
      <mass value="0.6"/>
      <origin rpy="0  0  0" xyz="0 0.1 0"/>
      <inertia ixx="0.00457331" ixy="0" ixz="0" iyy="0.02697040" iyz="0" izz="0.02375490"/>
    </inertial>
    <collision>
      <origin rpy="0  0  0" xyz="0 0 0"/>
      <geometry>
        <mesh filename="package://mrcp_trex_gripper_description/meshes/LSArm.STL" scale="1 1 1"/>
      </geometry>
    </collision>
    <visual>
      <origin rpy="0  0  0" xyz="0 0 0"/>
      <geometry>
        <mesh filename="package://mrcp_trex_gripper_description/meshes/LSArm.STL" scale="1 1 1"/>
      </geometry>
    </visual>
  </link>
  <joint name="Right_Bogie_joint" type="revolute">
    <parent link="Right_Rocker"/>
    <child link="Right_Bogie"/>
    <origin rpy="0 0 0" xyz="0.2 0.054 -0.06"/>
    <axis xyz="0 1 0"/>
    <limit effort="1" lower="-0.7853" upper="0.7853" velocity="20"/>
    <dynamics damping="1" friction="1"/>
  </joint>
  <link name="Left_Bogie">
    <inertial>
      <mass value="0.6"/>
      <origin rpy="0  0  0" xyz="0 -0.1 0"/>
      <inertia ixx="0.00457331" ixy="0" ixz="0" iyy="0.02697040" iyz="0" izz="0.02375490"/>
    </inertial>
    <collision>
      <origin rpy="0  0  0" xyz="0 0 0"/>
      <geometry>
        <mesh filename="package://mrcp_trex_gripper_description/meshes/RSArm.STL" scale="1 1 1"/>
      </geometry>
    </collision>
    <visual>
      <origin rpy="0  0  0" xyz="0 0 0"/>
      <geometry>
        <mesh filename="package://mrcp_trex_gripper_description/meshes/RSArm.STL" scale="1 1 1"/>
      </geometry>
    </visual>
  </link>
  <joint name="Left_Bogie_joint" type="revolute">
    <parent link="Left_Rocker"/>
    <child link="Left_Bogie"/>
    <origin rpy="0 0 0" xyz="0.2 -0.054 -0.06"/>
    <axis xyz="0 1 0"/>
    <limit effort="1" lower="-0.7853" upper="0.7853" velocity="20"/>
    <dynamics damping="1" friction="1"/>
  </joint>
  <link name="Servo4">
    <inertial>
      <mass value="0.4"/>
      <origin rpy="0  0  0" xyz="0 -0.07 -0.08"/>
      <inertia ixx="0.00160383" ixy="0" ixz="0" iyy="0.00114480" iyz="0" izz="0.00053229"/>
    </inertial>
    <collision>
      <origin rpy="0  0  0" xyz="0 0 0"/>
      <geometry>
        <mesh filename="package://mrcp_trex_gripper_description/meshes/StWh1.STL" scale="1 1 1"/>
      </geometry>
    </collision>
    <visual>
      <origin rpy="0  0  0" xyz="0 0 0"/>
      <geometry>
        <mesh filename="package://mrcp_trex_gripper_description/meshes/StWh1.STL" scale="1 1 1"/>
      </geometry>
    </visual>
  </link>
  <joint name="Servo4_joint" type="revolute">
    <parent link="Right_Bogie"/>
    <child link="Servo4"/>
    <origin rpy="0 0 0" xyz="0.2 0.165 0.03"/>
    <axis xyz="0 0 1"/>
    <limit effort="15" lower="-1.5708" upper="1.5708" velocity="0.2"/>
    <dynamics damping="1" friction="5"/>
  </joint>
  <link name="Wheel6">
    <inertial>
      <mass value="0.4"/>
      <origin rpy="0  0  0" xyz="0 0.04 0"/>
      <inertia ixx="0.000696" ixy="0" ixz="0" iyy="0.001044" iyz="0" izz="0.000696"/>
    </inertial>
    <collision>
      <origin rpy="0  0  0" xyz="0 0 0"/>
      <geometry>
        <mesh filename="package://mrcp_trex_gripper_description/meshes/Wheel.STL" scale="1 1 1"/>
      </geometry>
    </collision>
    <visual>
      <origin rpy="0  0  0" xyz="0 0 0"/>
      <geometry>
        <mesh filename="package://mrcp_trex_gripper_description/meshes/Wheel.STL" scale="1 1 1"/>
      </geometry>
    </visual>
  </link>
  <joint name="Motor6_joint" type="continuous">
    <parent link="Servo4"/>
    <child link="Wheel6"/>
    <origin rpy="0 0 0" xyz="0 -0.03 -0.142"/>
    <axis xyz="0 1 0"/>
    <limit effort="30" velocity="3"/>
    <dynamics damping="1" friction="5"/>
  </joint>
  <link name="Servo3">
    <inertial>
      <mass value="0.4"/>
      <origin rpy="0  0  0" xyz="0 -0.07 -0.08"/>
      <inertia ixx="0.00160383" ixy="0" ixz="0" iyy="0.00114480" iyz="0" izz="0.00053229"/>
    </inertial>
    <collision>
      <origin rpy="0  0  0" xyz="0 0 0"/>
      <geometry>
        <mesh filename="package://mrcp_trex_gripper_description/meshes/StWh1.STL" scale="1 1 1"/>
      </geometry>
    </collision>
    <visual>
      <origin rpy="0  0  0" xyz="0 0 0"/>
      <geometry>
        <mesh filename="package://mrcp_trex_gripper_description/meshes/StWh1.STL" scale="1 1 1"/>
      </geometry>
    </visual>
  </link>
  <joint name="Servo3_joint" type="revolute">
    <parent link="Left_Bogie"/>
    <child link="Servo3"/>
    <origin rpy="0 0 3.14159" xyz="0.2 -0.165 0.03"/>
    <axis xyz="0 0 1"/>
    <limit effort="15" lower="-1.5708" upper="1.5708" velocity="0.2"/>
    <dynamics damping="1" friction="5"/>
  </joint>
  <link name="Wheel5">
    <inertial>
      <mass value="0.4"/>
      <origin rpy="0  0  0" xyz="0 0.04 0"/>
      <inertia ixx="0.000696" ixy="0" ixz="0" iyy="0.001044" iyz="0" izz="0.000696"/>
    </inertial>
    <collision>
      <origin rpy="0  0  0" xyz="0 0 0"/>
      <geometry>
        <mesh filename="package://mrcp_trex_gripper_description/meshes/Wheel.STL" scale="1 1 1"/>
      </geometry>
    </collision>
    <visual>
      <origin rpy="0  0  0" xyz="0 0 0"/>
      <geometry>
        <mesh filename="package://mrcp_trex_gripper_description/meshes/Wheel.STL" scale="1 1 1"/>
      </geometry>
    </visual>
  </link>
  <joint name="Motor5_joint" type="continuous">
    <parent link="Servo3"/>
    <child link="Wheel5"/>
    <origin rpy="0 0 0" xyz="0 -0.03 -0.142"/>
    <axis xyz="0 1 0"/>
    <limit effort="30" velocity="3"/>
    <dynamics damping="1" friction="5"/>
  </joint>
  <link name="Wheel4">
    <inertial>
      <mass value="0.4"/>
      <origin rpy="0  0  0" xyz="0 0.04 0"/>
      <inertia ixx="0.000696" ixy="0" ixz="0" iyy="0.001044" iyz="0" izz="0.000696"/>
    </inertial>
    <collision>
      <origin rpy="0  0  0" xyz="0 0 0"/>
      <geometry>
        <mesh filename="package://mrcp_trex_gripper_description/meshes/Wheel.STL" scale="1 1 1"/>
      </geometry>
    </collision>
    <visual>
      <origin rpy="0  0  0" xyz="0 0 0"/>
      <geometry>
        <mesh filename="package://mrcp_trex_gripper_description/meshes/Wheel.STL" scale="1 1 1"/>
      </geometry>
    </visual>
  </link>
  <joint name="Motor4_joint" type="continuous">
    <parent link="Right_Bogie"/>
    <child link="Wheel4"/>
    <origin rpy="0 0 0" xyz="-0.200 0.130 -0.110"/>
    <axis xyz="0 1 0"/>
    <limit effort="30" velocity="3"/>
    <dynamics damping="1" friction="5"/>
  </joint>
  <link name="Wheel3">
    <inertial>
      <mass value="0.4"/>
      <origin rpy="0  0  0" xyz="0 0.04 0"/>
      <inertia ixx="0.000696" ixy="0" ixz="0" iyy="0.001044" iyz="0" izz="0.000696"/>
    </inertial>
    <collision>
      <origin rpy="0  0  0" xyz="0 0 0"/>
      <geometry>
        <mesh filename="package://mrcp_trex_gripper_description/meshes/Wheel.STL" scale="1 1 1"/>
      </geometry>
    </collision>
    <visual>
      <origin rpy="0  0  0" xyz="0 0 0"/>
      <geometry>
        <mesh filename="package://mrcp_trex_gripper_description/meshes/Wheel.STL" scale="1 1 1"/>
      </geometry>
    </visual>
  </link>
  <joint name="Motor3_joint" type="continuous">
    <parent link="Left_Bogie"/>
    <child link="Wheel3"/>
    <origin rpy="0 0 3.14159" xyz="-0.200 -0.130 -0.110"/>
    <axis xyz="0 1 0"/>
    <limit effort="30" velocity="3"/>
    <dynamics damping="1" friction="5"/>
  </joint>
  <link name="Servo2">
    <inertial>
      <mass value="0.4"/>
      <origin rpy="0  0  0" xyz="0 -0.07 -0.08"/>
      <inertia ixx="0.00160383" ixy="0" ixz="0" iyy="0.00114480" iyz="0" izz="0.00053229"/>
    </inertial>
    <collision>
      <origin rpy="0  0  0" xyz="0 0 0"/>
      <geometry>
        <mesh filename="package://mrcp_trex_gripper_description/meshes/StWh1.STL" scale="1 1 1"/>
      </geometry>
    </collision>
    <visual>
      <origin rpy="0  0  0" xyz="0 0 0"/>
      <geometry>
        <mesh filename="package://mrcp_trex_gripper_description/meshes/StWh1.STL" scale="1 1 1"/>
      </geometry>
    </visual>
  </link>
  <joint name="Servo2_joint" type="revolute">
    <parent link="Right_Rocker"/>
    <child link="Servo2"/>
    <origin rpy="0 0 0" xyz="-0.400 0.214 -0.04"/>
    <axis xyz="0 0 1"/>
    <limit effort="15" lower="-1.5708" upper="1.5708" velocity="0.2"/>
    <dynamics damping="1" friction="5"/>
  </joint>
  <link name="Wheel2">
    <inertial>
      <mass value="0.4"/>
      <origin rpy="0  0  0" xyz="0 0.04 0"/>
      <inertia ixx="0.000696" ixy="0" ixz="0" iyy="0.001044" iyz="0" izz="0.000696"/>
    </inertial>
    <collision>
      <origin rpy="0  0  0" xyz="0 0 0"/>
      <geometry>
        <mesh filename="package://mrcp_trex_gripper_description/meshes/Wheel.STL" scale="1 1 1"/>
      </geometry>
    </collision>
    <visual>
      <origin rpy="0  0  0" xyz="0 0 0"/>
      <geometry>
        <mesh filename="package://mrcp_trex_gripper_description/meshes/Wheel.STL" scale="1 1 1"/>
      </geometry>
    </visual>
  </link>
  <joint name="Motor2_joint" type="continuous">
    <parent link="Servo2"/>
    <child link="Wheel2"/>
    <origin rpy="0 0 0" xyz="0 -0.035 -0.140"/>
    <axis xyz="0 1 0"/>
    <limit effort="30" velocity="3"/>
    <dynamics damping="1" friction="5"/>
  </joint>
  <link name="Servo1">
    <inertial>
      <mass value="0.4"/>
      <origin rpy="0  0  0" xyz="0 -0.07 -0.08"/>
      <inertia ixx="0.00160383" ixy="0" ixz="0" iyy="0.00114480" iyz="0" izz="0.00053229"/>
    </inertial>
    <collision>
      <origin rpy="0  0  0" xyz="0 0 0"/>
      <geometry>
        <mesh filename="package://mrcp_trex_gripper_description/meshes/StWh1.STL" scale="1 1 1"/>
      </geometry>
    </collision>
    <visual>
      <origin rpy="0  0  0" xyz="0 0 0"/>
      <geometry>
        <mesh filename="package://mrcp_trex_gripper_description/meshes/StWh1.STL" scale="1 1 1"/>
      </geometry>
    </visual>
  </link>
  <joint name="Servo1_joint" type="revolute">
    <parent link="Left_Rocker"/>
    <child link="Servo1"/>
    <origin rpy="0 0 3.14159" xyz="-0.400 -0.214 -0.04"/>
    <axis xyz="0 0 1"/>
    <limit effort="15" lower="-1.5708" upper="1.5708" velocity="0.2"/>
    <dynamics damping="1" friction="5"/>
  </joint>
  <link name="Wheel1">
    <inertial>
      <mass value="0.4"/>
      <origin rpy="0  0  0" xyz="0 0.04 0"/>
      <inertia ixx="0.000696" ixy="0" ixz="0" iyy="0.001044" iyz="0" izz="0.000696"/>
    </inertial>
    <collision>
      <origin rpy="0  0  0" xyz="0 0 0"/>
      <geometry>
        <mesh filename="package://mrcp_trex_gripper_description/meshes/Wheel.STL" scale="1 1 1"/>
      </geometry>
    </collision>
    <visual>
      <origin rpy="0  0  0" xyz="0 0 0"/>
      <geometry>
        <mesh filename="package://mrcp_trex_gripper_description/meshes/Wheel.STL" scale="1 1 1"/>
      </geometry>
    </visual>
  </link>
  <joint name="Motor1_joint" type="continuous">
    <parent link="Servo1"/>
    <child link="Wheel1"/>
    <origin rpy="0 0 0" xyz="0 -0.035 -0.140"/>
    <axis xyz="0 1 0"/>
    <limit effort="30" velocity="3"/>
    <dynamics damping="1" friction="5"/>
  </joint>

  <!--++++++++++++++++++++++++++++++++++++++++++++     TREX robot arm links joints   ++++++++++++++++++++++++++++++++++++++++++++++++++++++++++-->

  <link name="link_1">
    <inertial>
      <origin rpy="0 0 0" xyz="-0.000141 0.0037255 0.023628"/>
      <mass value="2.9455"/>
      <inertia ixx="0.01138" ixy="-2.7095E-07" ixz="3.1715E-06" iyy="0.0096429" iyz="1.5373E-06" izz="0.020629"/>
    </inertial>
    <visual>
      <origin rpy="0 0 0" xyz="0 0 0"/>
      <geometry>
        <mesh filename="package://mrcp_trex_gripper_description/meshes/link_1.STL" scale="1 1 1"/>
      </geometry>
      <material name="">
        <color rgba="0.75294 0.75294 0.75294 1"/>
      </material>
    </visual>
    <collision>
      <origin rpy="0 0 0" xyz="0 0 0"/>
      <geometry>
        <mesh filename="package://mrcp_trex_gripper_description/meshes/link_1.STL" scale="1 1 1"/>
      </geometry>
    </collision>
  </link>
  <!-- ++++++++++++++++++++++++++++++++++++++++++++++++++   Joint between MRCP and TREX    ++++++++++++++++++++++++++++++++++++++++++++++++++ -->
  <joint name="arm_base_joint" type="fixed">
    <!-- <axis xyz="0 0 1"/> -->
    <parent link="body"/>
    <child link="link_1"/>
    <origin rpy="0 0 0" xyz="0 0 0.25"/>
  </joint>
  <!-- ++++++++++++++++++++++++++++++++++++++++++++++++++                                  ++++++++++++++++++++++++++++++++++++++++++++++++++ -->
  <link name="link_2">
    <inertial>
      <origin rpy="0 0 0" xyz="-0.01123 -0.0018406 0.051113"/>
      <mass value="2.9623"/>
      <inertia ixx="0.0015369" ixy="-2.9413E-05" ixz="2.4339E-05" iyy="0.0018827" iyz="4.0371E-06" izz="0.0013113"/>
    </inertial>
    <visual>
      <origin rpy="0 0 0" xyz="0 0 0"/>
      <geometry>
        <mesh filename="package://mrcp_trex_gripper_description/meshes/link_2.STL" scale="1 1 1"/>
      </geometry>
      <material name="">
        <color rgba="0.75294 0.75294 0.75294 1"/>
      </material>
    </visual>
    <collision>
      <origin rpy="0 0 0" xyz="0 0 0"/>
      <geometry>
        <mesh filename="package://mrcp_trex_gripper_description/meshes/link_2.STL" scale="1 1 1"/>
      </geometry>
    </collision>
  </link>
  <joint name="joint_1" type="revolute">
    <origin rpy="0 0 0" xyz="-0.0085035 0.003 0.072"/>
    <parent link="link_1"/>
    <child link="link_2"/>
    <axis xyz="0 0 -1"/>
    <limit effort="87" lower="-3.14" upper="3.14" velocity="2.1750"/>
    <dynamics damping="1.0"/>
    <!-- please check the effort, velocity and damping values -->
  </joint>
  <link name="link_3">
    <inertial>
      <origin rpy="0 0 0" xyz="0.11519 0.028267 0.21582"/>
      <mass value="2.0676"/>
      <inertia ixx="0.0055995" ixy="-0.00025414" ixz="-0.0027225" iyy="0.007635" iyz="-0.00031788" izz="0.0025763"/>
    </inertial>
    <visual>
      <origin rpy="0 0 0" xyz="0 0 0"/>
      <geometry>
        <mesh filename="package://mrcp_trex_gripper_description/meshes/link_3.STL" scale="1 1 1"/>
      </geometry>
      <material name="">
        <color rgba="0.75294 0.75294 0.75294 1"/>
      </material>
    </visual>
    <collision>
      <origin rpy="0 0 0" xyz="0 0 0"/>
      <geometry>
        <mesh filename="package://mrcp_trex_gripper_description/meshes/link_3.STL" scale="1 1 1"/>
      </geometry>
    </collision>
  </link>
  <joint name="joint_2" type="revolute">
    <origin rpy="0 0 0" xyz="0.0043365 -0.033328 0.0579"/>
    <parent link="link_2"/>
    <child link="link_3"/>
    <axis xyz="0.12903 -0.99164 0"/>
    <limit effort="87" lower="-0.47" upper="1.57" velocity="2.1750"/>
    <dynamics damping="1.0"/>
    <!-- please check the effort, velocity and damping values -->
  </joint>
  <link name="link_4">
    <inertial>
      <origin rpy="0 0 0" xyz="0.17298 0.031045 0.010118"/>
      <mass value="0.9251"/>
      <inertia ixx="0.00023722" ixy="-0.00019275" ixz="-0.00014277" iyy="0.0016807" iyz="-1.7763E-05" izz="0.001589"/>
    </inertial>
    <visual>
      <origin rpy="0 0 0" xyz="0 0 0"/>
      <geometry>
        <mesh filename="package://mrcp_trex_gripper_description/meshes/link_4.STL" scale="1 1 1"/>
      </geometry>
      <material name="">
        <color rgba="0.75294 0.75294 0.75294 1"/>
      </material>
    </visual>
    <collision>
      <origin rpy="0 0 0" xyz="0 0 0"/>
      <geometry>
        <mesh filename="package://mrcp_trex_gripper_description/meshes/link_4.STL" scale="1 1 1"/>
      </geometry>
    </collision>
  </link>
  <joint name="joint_3" type="revolute">
    <origin rpy="0 0 0" xyz="0.1495 0.050117 0.25703"/>
    <parent link="link_3"/>
    <child link="link_4"/>
    <axis xyz="0.12903 -0.99164 0"/>
    <limit effort="87" lower="-0.9" upper="1.5" velocity="2.1750"/>
    <dynamics damping="1.0"/>
    <!-- please check the effort, velocity and damping values -->
  </joint>
  <link name="link_5">
    <inertial>
      <origin rpy="0 0 0" xyz="0.039525 0.033991 -0.068386"/>
      <mass value="0.69913"/>
      <inertia ixx="0.00024803" ixy="-7.144E-06" ixz="2.9982E-05" iyy="0.00024618" iyz="1.7465E-05" izz="0.0001813"/>
    </inertial>
    <visual>
      <origin rpy="0 0 0" xyz="0 0 0"/>
      <geometry>
        <mesh filename="package://mrcp_trex_gripper_description/meshes/link_5.STL" scale="1 1 1"/>
      </geometry>
      <material name="">
        <color rgba="0.75294 0.75294 0.75294 1"/>
      </material>
    </visual>
    <collision>
      <origin rpy="0 0 0" xyz="0 0 0"/>
      <geometry>
        <mesh filename="package://mrcp_trex_gripper_description/meshes/link_5.STL" scale="1 1 1"/>
      </geometry>
    </collision>
  </link>
  <joint name="joint_4" type="revolute">
    <origin rpy="0 0 0" xyz="0.22469 0.0072929 0.023651"/>
    <parent link="link_4"/>
    <child link="link_5"/>
    <axis xyz="0.12903 -0.99164 0"/>    
    <limit effort="87" lower="-0.9" upper="3.14" velocity="2.1750"/>
    <dynamics damping="1.0"/>
    <!-- please check the effort, velocity and damping values -->
  </joint>
  <link name="link_6">
    <inertial>
      <origin rpy="0 0 0" xyz="0.025787 0.0056057 -0.043459"/>
      <mass value="0.30019"/>
      <inertia ixx="0.00021201" ixy="-4.0828E-05" ixz="1.8446E-05" iyy="0.00019155" iyz="-1.7801E-05" izz="0.00017435"/>
    </inertial>
    <visual>
      <origin rpy="0 0 0" xyz="0 0 0"/>
      <geometry>
        <mesh filename="package://mrcp_trex_gripper_description/meshes/link_6.STL" scale="1 1 1"/>
      </geometry>
      <material name="">
        <color rgba="0.75294 0.75294 0.75294 1"/>
      </material>
    </visual>
    <collision>
      <origin rpy="0 0 0" xyz="0 0 0"/>
      <geometry>
        <mesh filename="package://mrcp_trex_gripper_description/meshes/link_6.STL" scale="1 1 1"/>
      </geometry>
    </collision>
  </link>
  <joint name="joint_5" type="revolute">
    <origin rpy="0 0 0" xyz="0.041015 0.029287 -0.094022"/>
    <parent link="link_5"/>
    <child link="link_6"/>
    <axis xyz="0.42384 0.05515 -0.90406"/>   
    <limit effort="87" lower="-3.14" upper="3.14" velocity="2.1750"/>
    <dynamics damping="1.0"/>
    <!-- please check the effort, velocity and damping values -->
  </joint>


  <!--++++++++++++++++++++++++++++++++++++++++++++     MRCP TRANSMISSIONS   ++++++++++++++++++++++++++++++++++++++++++++++++++++++++++-->

<!--   <transmission name="Right_Rocker_tran">
    <type>transmission_interface/SimpleTransmission</type>
    <joint name="Right_Rocker_joint">
      <hardwareInterface>hardware_interface/EffortJointInterface</hardwareInterface>
    </joint>
    <actuator name="Right_Rocker_motor">
      <hardwareInterface>EffortJointInterface</hardwareInterface>
      <mechanicalReduction>1</mechanicalReduction>
    </actuator>
  </transmission> -->

<!--   <transmission name="Left_Rocker_tran">
    <type>transmission_interface/SimpleTransmission</type>
    <joint name="Left_Rocker_joint">
      <hardwareInterface>hardware_interface/EffortJointInterface</hardwareInterface>
    </joint>
    <actuator name="Left_Rocker_motor">
      <hardwareInterface>EffortJointInterface</hardwareInterface>
      <mechanicalReduction>1</mechanicalReduction>
    </actuator>
  </transmission> -->

  <transmission name="Right_Bogie_tran">
    <type>transmission_interface/SimpleTransmission</type>
    <joint name="Right_Bogie_joint">
      <hardwareInterface>hardware_interface/EffortJointInterface</hardwareInterface>
    </joint>
    <actuator name="Right_Bogie_motor">
      <hardwareInterface>EffortJointInterface</hardwareInterface>
      <mechanicalReduction>1</mechanicalReduction>
    </actuator>
  </transmission>

  <transmission name="Servo2_tran">
    <type>transmission_interface/SimpleTransmission</type>
    <joint name="Servo2_joint">
      <hardwareInterface>hardware_interface/EffortJointInterface</hardwareInterface>
    </joint>
    <actuator name="Servo2_motor">
      <hardwareInterface>EffortJointInterface</hardwareInterface>
      <mechanicalReduction>1</mechanicalReduction>
    </actuator>
  </transmission>

  <transmission name="Left_Bogie_tran">
    <type>transmission_interface/SimpleTransmission</type>
    <joint name="Left_Bogie_joint">
      <hardwareInterface>hardware_interface/EffortJointInterface</hardwareInterface>
    </joint>
    <actuator name="Left_Bogie_motor">
      <hardwareInterface>EffortJointInterface</hardwareInterface>
      <mechanicalReduction>1</mechanicalReduction>
    </actuator>
  </transmission>

  <transmission name="Servo1_tran">
    <type>transmission_interface/SimpleTransmission</type>
    <joint name="Servo1_joint">
      <hardwareInterface>hardware_interface/EffortJointInterface</hardwareInterface>
    </joint>
    <actuator name="Servo1_motor">
      <hardwareInterface>EffortJointInterface</hardwareInterface>
      <mechanicalReduction>1</mechanicalReduction>
    </actuator>
  </transmission>

  <transmission name="Motor2_tran">
    <type>transmission_interface/SimpleTransmission</type>
    <joint name="Motor2_joint">
      <hardwareInterface>hardware_interface/EffortJointInterface</hardwareInterface>
    </joint>
    <actuator name="Motor2_motor">
      <hardwareInterface>EffortJointInterface</hardwareInterface>
      <mechanicalReduction>1</mechanicalReduction>
    </actuator>
  </transmission>

  <transmission name="Motor4_tran">
    <type>transmission_interface/SimpleTransmission</type>
    <joint name="Motor4_joint">
      <hardwareInterface>hardware_interface/EffortJointInterface</hardwareInterface>
    </joint>
    <actuator name="Motor4_motor">
      <hardwareInterface>EffortJointInterface</hardwareInterface>
      <mechanicalReduction>1</mechanicalReduction>
    </actuator>
  </transmission>

  <transmission name="Servo4_tran">
    <type>transmission_interface/SimpleTransmission</type>
    <joint name="Servo4_joint">
      <hardwareInterface>hardware_interface/EffortJointInterface</hardwareInterface>
    </joint>
    <actuator name="Servo4_motor">
      <hardwareInterface>EffortJointInterface</hardwareInterface>
      <mechanicalReduction>1</mechanicalReduction>
    </actuator>
  </transmission>

  <transmission name="Motor1_tran">
    <type>transmission_interface/SimpleTransmission</type>
    <joint name="Motor1_joint">
      <hardwareInterface>hardware_interface/EffortJointInterface</hardwareInterface>
    </joint>
    <actuator name="Motor1_motor">
      <hardwareInterface>EffortJointInterface</hardwareInterface>
      <mechanicalReduction>1</mechanicalReduction>
    </actuator>
  </transmission>

  <transmission name="Servo3_tran">
    <type>transmission_interface/SimpleTransmission</type>
    <joint name="Servo3_joint">
      <hardwareInterface>hardware_interface/EffortJointInterface</hardwareInterface>
    </joint>
    <actuator name="Servo3_motor">
      <hardwareInterface>EffortJointInterface</hardwareInterface>
      <mechanicalReduction>1</mechanicalReduction>
    </actuator>
  </transmission>

  <transmission name="Motor3_tran">
    <type>transmission_interface/SimpleTransmission</type>
    <joint name="Motor3_joint">
      <hardwareInterface>hardware_interface/EffortJointInterface</hardwareInterface>
    </joint>
    <actuator name="Motor3_motor">
      <hardwareInterface>EffortJointInterface</hardwareInterface>
      <mechanicalReduction>1</mechanicalReduction>
    </actuator>
  </transmission>

  <transmission name="Motor6_tran">
    <type>transmission_interface/SimpleTransmission</type>
    <joint name="Motor6_joint">
      <hardwareInterface>hardware_interface/EffortJointInterface</hardwareInterface>
    </joint>
    <actuator name="Motor6_motor">
      <hardwareInterface>EffortJointInterface</hardwareInterface>
      <mechanicalReduction>1</mechanicalReduction>
    </actuator>
  </transmission>

  <transmission name="Motor5_tran">
    <type>transmission_interface/SimpleTransmission</type>
    <joint name="Motor5_joint">
      <hardwareInterface>hardware_interface/EffortJointInterface</hardwareInterface>
    </joint>
    <actuator name="Motor5_motor">
      <hardwareInterface>EffortJointInterface</hardwareInterface>
      <mechanicalReduction>1</mechanicalReduction>
    </actuator>
  </transmission>

  <!--++++++++++++++++++++++++++++++++++++++++++++     TREX ARM TRANSIMISSIONS   ++++++++++++++++++++++++++++++++++++++++++++++++++++++++++-->

 <!-- This block connects the joints to actuators (motor), which inform both simulation and visualization of the robot -->
  <transmission name="trans_joint_1">
    <type>transmission_interface/SimpleTransmission</type>
    <joint name="joint_1">
      <hardwareInterface>hardware_interface/PositionJointInterface</hardwareInterface>
      <!-- Please note that if you want to spawn the robot arm in Gazebo you should choose the PositionJointInterface as hardwareInterface to obtain a standing model -->
    </joint>
    <actuator name="joint_1_motor">
      <hardwareInterface>hardware_interface/PositionJointInterface</hardwareInterface>
      <mechanicalReduction>1</mechanicalReduction>
    </actuator>
  </transmission>
  <transmission name="trans_joint_2">
    <type>transmission_interface/SimpleTransmission</type>
    <joint name="joint_2">
      <hardwareInterface>hardware_interface/PositionJointInterface</hardwareInterface>
    </joint>
    <actuator name="joint_2_motor">
      <hardwareInterface>hardware_interface/PositionJointInterface</hardwareInterface>
      <mechanicalReduction>1</mechanicalReduction>
    </actuator>
  </transmission>
  <transmission name="trans_joint_3">
    <type>transmission_interface/SimpleTransmission</type>
    <joint name="joint_3">
      <hardwareInterface>hardware_interface/PositionJointInterface</hardwareInterface>
    </joint>
    <actuator name="joint_3_motor">
      <hardwareInterface>hardware_interface/PositionJointInterface</hardwareInterface>
      <mechanicalReduction>1</mechanicalReduction>
    </actuator>
  </transmission>
  <transmission name="trans_joint_4">
    <type>transmission_interface/SimpleTransmission</type>
    <joint name="joint_4">
      <hardwareInterface>hardware_interface/PositionJointInterface</hardwareInterface>
    </joint>
    <actuator name="joint_4_motor">
      <hardwareInterface>hardware_interface/PositionJointInterface</hardwareInterface>
      <mechanicalReduction>1</mechanicalReduction>
    </actuator>
  </transmission>
  <transmission name="trans_joint_5">
    <type>transmission_interface/SimpleTransmission</type>
    <joint name="joint_5">
      <hardwareInterface>hardware_interface/PositionJointInterface</hardwareInterface>
    </joint>
    <actuator name="joint_5_motor">
      <hardwareInterface>hardware_interface/PositionJointInterface</hardwareInterface>
      <mechanicalReduction>1</mechanicalReduction>
    </actuator>
  </transmission>


  <!--++++++++++++++++++++++++++++++++++++++++++++     ros_control plugin Gazebo   ++++++++++++++++++++++++++++++++++++++++++++++++++++++++++-->

<!--   <gazebo>
    <plugin filename="libgazebo_ros_control.so" name="gazebo_ros_control">
      <robotNamespace>/mrcp_trex_gripper</robotNamespace>
    </plugin>
  </gazebo> -->

   <!-- ros_control plugin -->
  <gazebo>
    <!--To link Gazebo and ROS, we specify the plugin in the URDF-->
    <plugin name="gazebo_ros_control" filename="libgazebo_ros_control.so">
      <robotNamespace>/mrcp_trex_gripper</robotNamespace>
      <robotSimType>gazebo_ros_control/DefaultRobotHWSim</robotSimType>
      <legacyModeNS>true</legacyModeNS>
    </plugin>
  </gazebo>

  <gazebo>
    <plugin name="joint_state_publisher" filename="libgazebo_ros_joint_state_publisher.so">
      <jointName>joint_1, joint_2, joint_3, joint_4, joint_5</jointName>
    </plugin>
  </gazebo>

  <!--++++++++++++++++++++++++++++++++++++++++++++     Gazebo MRCP  ++++++++++++++++++++++++++++++++++++++++++++++++++++++++++-->

<!--   <gazebo>
      <plugin name="diff_drive_controller" filename="libgazebo_ros_diff_drive.so">
        <legacyMode>false</legacyMode>
        <alwaysOn>true</alwaysOn>
        <updateRate>1000.0</updateRate>
        <leftJoint>front_left_wheel_joint, rear_left_wheel_joint</leftJoint>
        <rightJoint>front_right_wheel_joint, rear_right_wheel_joint</rightJoint>
        <wheelSeparation>0.5</wheelSeparation>
        <wheelDiameter>0.2</wheelDiameter>
        <wheelTorque>10</wheelTorque>
        <publishTf>1</publishTf>
        <odometryFrame>map</odometryFrame>
        <commandTopic>cmd_vel</commandTopic>
        <odometryTopic>odom</odometryTopic>
        <robotBaseFrame>base_link</robotBaseFrame>
        <wheelAcceleration>2.8</wheelAcceleration>
        <publishWheelJointState>true</publishWheelJointState>
        <publishWheelTF>false</publishWheelTF>
        <odometrySource>world</odometrySource>
        <rosDebugLevel>Debug</rosDebugLevel>
      </plugin>
</gazebo> -->

  <gazebo reference="Wheel1">
    <mu1 value="5"/>
    <!-- Columb friction coefficient in fdir1 direction -->
    <mu2 value="1"/>
    <!-- Columb friction in perpendicular direction to fdir1 -->
    <kp value="2000000"/>
    <!-- contact stiffness -->
    <kd value="1.0"/>
    <!-- contact damping -->
    <material>Gazebo/Grey</material>
  </gazebo>
  <gazebo reference="Wheel2">
    <mu1 value="5"/>
    <!-- Columb friction coefficient in fdir1 direction -->
    <mu2 value="1"/>
    <!-- Columb friction in perpendicular direction to fdir1 -->
    <kp value="2000000"/>
    <!-- contact stiffness -->
    <kd value="1.0"/>
    <!-- contact damping -->
    <material>Gazebo/Grey</material>
  </gazebo>
  <gazebo reference="Wheel3">
    <mu1 value="5"/>
    <!-- Columb friction coefficient in fdir1 direction -->
    <mu2 value="1"/>
    <!-- Columb friction in perpendicular direction to fdir1 -->
    <kp value="2000000"/>
    <!-- contact stiffness -->
    <kd value="1.0"/>
    <!-- contact damping -->
    <material>Gazebo/Grey</material>
  </gazebo>
  <gazebo reference="Wheel4">
    <mu1 value="5"/>
    <!-- Columb friction coefficient in fdir1 direction -->
    <mu2 value="1"/>
    <!-- Columb friction in perpendicular direction to fdir1 -->
    <kp value="2000000"/>
    <!-- contact stiffness -->
    <kd value="1.0"/>
    <!-- contact damping -->
    <material>Gazebo/Grey</material>
  </gazebo>
  <gazebo reference="Wheel5">
    <mu1 value="5"/>
    <!-- Columb friction coefficient in fdir1 direction -->
    <mu2 value="1"/>
    <!-- Columb friction in perpendicular direction to fdir1 -->
    <kp value="2000000"/>
    <!-- contact stiffness -->
    <kd value="1.0"/>
    <!-- contact damping -->
    <material>Gazebo/Grey</material>
  </gazebo>
  <gazebo reference="Wheel6">
    <mu1 value="5"/>
    <!-- Columb friction coefficient in fdir1 direction -->
    <mu2 value="1"/>
    <!-- Columb friction in perpendicular direction to fdir1 -->
    <kp value="2000000"/>
    <!-- contact stiffness -->
    <kd value="1.0"/>
    <!-- contact damping -->
    <material>Gazebo/Grey</material>
  </gazebo>




  <gazebo reference="link_1">
    <material>Gazebo/Grey</material>
    <mu1>0.2</mu1>
    <mu2>0.2</mu2>
    <!-- <selfCollide>true</selfCollide> -->
  </gazebo>
  <gazebo reference="link_2">
    <material>Gazebo/Blue</material>
    <mu1>0.2</mu1>
    <mu2>0.2</mu2>
  </gazebo>
  <gazebo reference="link_3">
    <material>Gazebo/White</material>
    <mu1>0.2</mu1>
    <mu2>0.2</mu2>
  </gazebo>
  <gazebo reference="link_4">
    <material>Gazebo/Red</material>
    <mu1>0.2</mu1>
    <mu2>0.2</mu2>
  </gazebo>

  <gazebo reference="link_5">
    <material>Gazebo/Green</material>
    <mu1>0.2</mu1>
    <mu2>0.2</mu2>
  </gazebo>
  <gazebo reference="link_6">
    <material>Gazebo/Yellow</material>
    <mu1>0.2</mu1>
    <mu2>0.2</mu2>
  </gazebo>


</robot>

