<?xml version="1.0" ?>
<!-- =================================================================================== -->
<!-- |    This document was autogenerated by xacro from trex_gripper_urdf.urdf         | -->
<!-- |    EDITING THIS FILE BY HAND IS NOT RECOMMENDED                                 | -->
<!-- =================================================================================== -->
<!-- This URDF was automatically created by SolidWorks to URDF Exporter! Originally created by Stephen Brawner (brawner@gmail.com) 
     Commit Version: 1.6.0-1-g15f4949  Build Version: 1.6.7594.29634
     For more information, please see http://wiki.ros.org/sw_urdf_exporter -->
<robot name="trex_gripper_urdf">
  <link name="world"/>
  <link name="link_1">
    <inertial>
      <origin rpy="0 0 0" xyz="-0.000141 0.0037255 0.023628"/>
      <mass value="2.9455"/>
      <inertia ixx="0.01138" ixy="-2.7095E-07" ixz="3.1715E-06" iyy="0.0096429" iyz="1.5373E-06" izz="0.020629"/>
    </inertial>
    <visual>
      <origin rpy="0 0 0" xyz="0 0 0"/>
      <geometry>
        <mesh filename="package://trex_gripper_urdf/meshes/link_1.STL"/>
      </geometry>
      <material name="">
        <color rgba="0.75294 0.75294 0.75294 1"/>
      </material>
    </visual>
    <collision>
      <origin rpy="0 0 0" xyz="0 0 0"/>
      <geometry>
        <mesh filename="package://trex_gripper_urdf/meshes/link_1.STL"/>
      </geometry>
    </collision>
  </link>
  <joint name="virtual_joint" type="fixed">
    <parent link="world"/>
    <child link="link_1"/>
    <origin rpy="0 0 0" xyz="0 0 0.1"/>
    <dynamics damping="100" friction="100.0"/>
    <!-- please check the damping and friction values -->
  </joint>
  <link name="link_2">
    <inertial>
      <origin rpy="0 0 0" xyz="-0.01123 -0.0018406 0.051113"/>
      <mass value="2.9623"/>
      <inertia ixx="0.0015369" ixy="-2.9413E-05" ixz="2.4339E-05" iyy="0.0018827" iyz="4.0371E-06" izz="0.0013113"/>
    </inertial>
    <visual>
      <origin rpy="0 0 0" xyz="0 0 0"/>
      <geometry>
        <mesh filename="package://trex_gripper_urdf/meshes/link_2.STL"/>
      </geometry>
      <material name="">
        <color rgba="0.75294 0.75294 0.75294 1"/>
      </material>
    </visual>
    <collision>
      <origin rpy="0 0 0" xyz="0 0 0"/>
      <geometry>
        <mesh filename="package://trex_gripper_urdf/meshes/link_2.STL"/>
      </geometry>
    </collision>
  </link>
  <joint name="joint_1" type="revolute">
    <origin rpy="0 0 0" xyz="-0.0085035 0.003 0.072"/>
    <parent link="link_1"/>
    <child link="link_2"/>
    <axis xyz="0 0 -1"/>
    <limit effort="87" lower="-3.14" upper="3.14" velocity="2.1750"/>
    <dynamics damping="1.0"/>
    <!-- please check the effort, velocity and damping values -->
  </joint>
  <link name="link_3">
    <inertial>
      <origin rpy="0 0 0" xyz="0.11519 0.028267 0.21582"/>
      <mass value="2.0676"/>
      <inertia ixx="0.0055995" ixy="-0.00025414" ixz="-0.0027225" iyy="0.007635" iyz="-0.00031788" izz="0.0025763"/>
    </inertial>
    <visual>
      <origin rpy="0 0 0" xyz="0 0 0"/>
      <geometry>
        <mesh filename="package://trex_gripper_urdf/meshes/link_3.STL"/>
      </geometry>
      <material name="">
        <color rgba="0.75294 0.75294 0.75294 1"/>
      </material>
    </visual>
    <collision>
      <origin rpy="0 0 0" xyz="0 0 0"/>
      <geometry>
        <mesh filename="package://trex_gripper_urdf/meshes/link_3.STL"/>
      </geometry>
    </collision>
  </link>
  <joint name="joint_2" type="revolute">
    <origin rpy="0 0 0" xyz="0.0043365 -0.033328 0.0579"/>
    <parent link="link_2"/>
    <child link="link_3"/>
    <axis xyz="0.12903 -0.99164 0"/>
    <limit effort="87" lower="-0.47" upper="1.57" velocity="2.1750"/>
    <dynamics damping="1.0"/>
    <!-- please check the effort, velocity and damping values -->
  </joint>
  <link name="link_4">
    <inertial>
      <origin rpy="0 0 0" xyz="0.17298 0.031045 0.010118"/>
      <mass value="0.9251"/>
      <inertia ixx="0.00023722" ixy="-0.00019275" ixz="-0.00014277" iyy="0.0016807" iyz="-1.7763E-05" izz="0.001589"/>
    </inertial>
    <visual>
      <origin rpy="0 0 0" xyz="0 0 0"/>
      <geometry>
        <mesh filename="package://trex_gripper_urdf/meshes/link_4.STL"/>
      </geometry>
      <material name="">
        <color rgba="0.75294 0.75294 0.75294 1"/>
      </material>
    </visual>
    <collision>
      <origin rpy="0 0 0" xyz="0 0 0"/>
      <geometry>
        <mesh filename="package://trex_gripper_urdf/meshes/link_4.STL"/>
      </geometry>
    </collision>
  </link>
  <joint name="joint_3" type="revolute">
    <origin rpy="0 0 0" xyz="0.1495 0.050117 0.25703"/>
    <parent link="link_3"/>
    <child link="link_4"/>
    <axis xyz="0.12903 -0.99164 0"/>
    <limit effort="87" lower="-0.9" upper="1.5" velocity="2.1750"/>
    <dynamics damping="1.0"/>
    <!-- please check the effort, velocity and damping values -->
  </joint>
  <link name="link_5">
    <inertial>
      <origin rpy="0 0 0" xyz="0.039525 0.033991 -0.068386"/>
      <mass value="0.69913"/>
      <inertia ixx="0.00024803" ixy="-7.144E-06" ixz="2.9982E-05" iyy="0.00024618" iyz="1.7465E-05" izz="0.0001813"/>
    </inertial>
    <visual>
      <origin rpy="0 0 0" xyz="0 0 0"/>
      <geometry>
        <mesh filename="package://trex_gripper_urdf/meshes/link_5.STL"/>
      </geometry>
      <material name="">
        <color rgba="0.75294 0.75294 0.75294 1"/>
      </material>
    </visual>
    <collision>
      <origin rpy="0 0 0" xyz="0 0 0"/>
      <geometry>
        <mesh filename="package://trex_gripper_urdf/meshes/link_5.STL"/>
      </geometry>
    </collision>
  </link>
  <joint name="joint_4" type="revolute">
    <origin rpy="0 0 0" xyz="0.22469 0.0072929 0.023651"/>
    <parent link="link_4"/>
    <child link="link_5"/>
    <axis xyz="0.12903 -0.99164 0"/>    
    <limit effort="87" lower="-0.9" upper="3.14" velocity="2.1750"/>
    <dynamics damping="1.0"/>
    <!-- please check the effort, velocity and damping values -->
  </joint>
  <link name="link_6">
    <inertial>
      <origin rpy="0 0 0" xyz="0.025787 0.0056057 -0.043459"/>
      <mass value="0.30019"/>
      <inertia ixx="0.00021201" ixy="-4.0828E-05" ixz="1.8446E-05" iyy="0.00019155" iyz="-1.7801E-05" izz="0.00017435"/>
    </inertial>
    <visual>
      <origin rpy="0 0 0" xyz="0 0 0"/>
      <geometry>
        <mesh filename="package://trex_gripper_urdf/meshes/link_6.STL"/>
      </geometry>
      <material name="">
        <color rgba="0.75294 0.75294 0.75294 1"/>
      </material>
    </visual>
    <collision>
      <origin rpy="0 0 0" xyz="0 0 0"/>
      <geometry>
        <mesh filename="package://trex_gripper_urdf/meshes/link_6.STL"/>
      </geometry>
    </collision>
  </link>
  <joint name="joint_5" type="revolute">
    <origin rpy="0 0 0" xyz="0.041015 0.029287 -0.094022"/>
    <parent link="link_5"/>
    <child link="link_6"/>
    <axis xyz="0.42384 0.05515 -0.90406"/>   
    <limit effort="87" lower="-3.14" upper="3.14" velocity="2.1750"/>
    <dynamics damping="1.0"/>
    <!-- please check the effort, velocity and damping values -->
  </joint>

    <!-- ros_control plugin -->
  <gazebo>
    <!--To link Gazebo and ROS, we specify the plugin in the URDF-->
    <plugin name="gazebo_ros_control" filename="libgazebo_ros_control.so">
      <robotNamespace>/trex_gripper_urdf</robotNamespace>
      <robotSimType>gazebo_ros_control/DefaultRobotHWSim</robotSimType>
      <legacyModeNS>true</legacyModeNS>
    </plugin>
  </gazebo>

  <gazebo reference="link_1">
    <material>Gazebo/Grey</material>
    <mu1>0.2</mu1>
    <mu2>0.2</mu2>
    <!-- <selfCollide>true</selfCollide> -->
  </gazebo>
  <gazebo reference="link_2">
    <material>Gazebo/Blue</material>
    <mu1>0.2</mu1>
    <mu2>0.2</mu2>
  </gazebo>
  <gazebo reference="link_3">
    <material>Gazebo/White</material>
    <mu1>0.2</mu1>
    <mu2>0.2</mu2>
  </gazebo>
  <gazebo reference="link_4">
    <material>Gazebo/Red</material>
    <mu1>0.2</mu1>
    <mu2>0.2</mu2>
  </gazebo>

  <gazebo reference="link_5">
    <material>Gazebo/Green</material>
    <mu1>0.2</mu1>
    <mu2>0.2</mu2>
  </gazebo>
  <gazebo reference="link_6">
    <material>Gazebo/Yellow</material>
    <mu1>0.2</mu1>
    <mu2>0.2</mu2>
  </gazebo>

  <!-- This block connects the joints to actuators (motor), which inform both simulation and visualization of the robot -->
  <transmission name="trans_joint_1">
    <type>transmission_interface/SimpleTransmission</type>
    <joint name="joint_1">
      <hardwareInterface>hardware_interface/PositionJointInterface</hardwareInterface>
      <!-- Please note that if you want to spawn the robot arm in Gazebo you should choose the PositionJointInterface as hardwareInterface to obtain a standing model -->
    </joint>
    <actuator name="joint_1_motor">
      <hardwareInterface>hardware_interface/PositionJointInterface</hardwareInterface>
      <mechanicalReduction>1</mechanicalReduction>
    </actuator>
  </transmission>
  <transmission name="trans_joint_2">
    <type>transmission_interface/SimpleTransmission</type>
    <joint name="joint_2">
      <hardwareInterface>hardware_interface/PositionJointInterface</hardwareInterface>
    </joint>
    <actuator name="joint_2_motor">
      <hardwareInterface>hardware_interface/PositionJointInterface</hardwareInterface>
      <mechanicalReduction>1</mechanicalReduction>
    </actuator>
  </transmission>
  <transmission name="trans_joint_3">
    <type>transmission_interface/SimpleTransmission</type>
    <joint name="joint_3">
      <hardwareInterface>hardware_interface/PositionJointInterface</hardwareInterface>
    </joint>
    <actuator name="joint_3_motor">
      <hardwareInterface>hardware_interface/PositionJointInterface</hardwareInterface>
      <mechanicalReduction>1</mechanicalReduction>
    </actuator>
  </transmission>
  <transmission name="trans_joint_4">
    <type>transmission_interface/SimpleTransmission</type>
    <joint name="joint_4">
      <hardwareInterface>hardware_interface/PositionJointInterface</hardwareInterface>
    </joint>
    <actuator name="joint_4_motor">
      <hardwareInterface>hardware_interface/PositionJointInterface</hardwareInterface>
      <mechanicalReduction>1</mechanicalReduction>
    </actuator>
  </transmission>
  <transmission name="trans_joint_5">
    <type>transmission_interface/SimpleTransmission</type>
    <joint name="joint_5">
      <hardwareInterface>hardware_interface/PositionJointInterface</hardwareInterface>
    </joint>
    <actuator name="joint_5_motor">
      <hardwareInterface>hardware_interface/PositionJointInterface</hardwareInterface>
      <mechanicalReduction>1</mechanicalReduction>
    </actuator>
  </transmission>

</robot>


<!-- PositionJointInterface -->